<?xml version="1.0"?>
<robot xmlns:xacro="http://www.ros.org/wiki/xacro">

  <xacro:include filename="inertial_macros.xacro"/>

  <!-- Materials -->
  <material name="gray"><color rgba="0.6 0.6 0.6 1.0"/></material>
  <material name="black"><color rgba="0.05 0.05 0.05 1.0"/></material>
  <material name="red"><color rgba="0.8 0.1 0.1 1.0"/></material>
  <material name="blue"><color rgba="0.2 0.2 1.0 1.0"/></material>

  <!-- Base dimensions -->
  <xacro:property name="base_x" value="0.50"/>
  <xacro:property name="base_y" value="0.30"/>
  <xacro:property name="base_z" value="0.18"/>

  <!-- Wheel dimensions -->
  <xacro:property name="wheel_r" value="0.10"/>

  <xacro:property name="wheel_w" value="0.03"/>

  <!-- Frame heights -->
  <!-- base_footprint is on the ground -->
  <!-- base_link is at chassis centre -->
  <xacro:property name="base_link_z" value="${wheel_r + base_z/2}"/>

  <!-- Wheel positions relative to base_link -->
  <xacro:property name="wheel_x_front" value="0.18"/>
  <xacro:property name="wheel_x_rear"  value="-0.18"/>
  <xacro:property name="wheel_y" value="${base_y/2 + wheel_w/2}"/>
  <xacro:property name="wheel_z" value="${-base_z/2}"/>

  <!-- Ground-projected frame -->
  <link name="base_footprint"/>

  <!-- Main body frame -->
  <link name="base_link">
    <visual>
      <origin xyz="0 0 0" rpy="0 0 0"/>
      <geometry>
        <box size="${base_x} ${base_y} ${base_z}"/>
      </geometry>
      <material name="gray"/>
    </visual>

    <collision>
      <origin xyz="0 0 0" rpy="0 0 0"/>
      <geometry>
        <box size="${base_x} ${base_y} ${base_z}"/>
      </geometry>
    </collision>

    <xacro:inertial_box mass="10.0" x="${base_x}" y="${base_y}" z="${base_z}">
      <origin xyz="0 0 0" rpy="0 0 0"/>
    </xacro:inertial_box>
  </link>

  <!-- Lift base_link above the ground -->
  <joint name="base_footprint_joint" type="fixed">
    <parent link="base_footprint"/>
    <child link="base_link"/>
    <origin xyz="0 0 ${base_link_z}" rpy="0 0 0"/>
  </joint>

  <gazebo reference="base_link">
    <material>Gazebo/Grey</material>
  </gazebo>

  <!-- Wheel macro -->
  <xacro:macro name="wheel_link" params="name">
    <link name="${name}">
      <visual>
        <origin xyz="0 0 0" rpy="${pi/2} 0 0"/>
        <geometry>
          <cylinder radius="${wheel_r}" length="${wheel_w}"/>
        </geometry>
        <material name="red"/>
      </visual>

      <collision>
        <origin xyz="0 0 0" rpy="${pi/2} 0 0"/>
        <geometry>
          <cylinder radius="${wheel_r*0.98}" length="${wheel_w*0.95}"/>
        </geometry>
      </collision>

      <xacro:inertial_cylinder mass="0.5" length="${wheel_w}" radius="${wheel_r}">
        <origin xyz="0 0 0" rpy="0 0 0"/>
      </xacro:inertial_cylinder>
    </link>

    <gazebo reference="${name}">
      <material>Gazebo/Red</material>
    </gazebo>

    <gazebo reference="${name}">
      <fdir1>1 0 0</fdir1>
      <mu1>1.4</mu1>
      <mu2>0.2</mu2>
      <slip1>0.0</slip1>
      <slip2>0.0</slip2>
    </gazebo>
  </xacro:macro>

  <!-- Wheels -->
  <xacro:wheel_link name="front_left_wheel"/>
  <xacro:wheel_link name="front_right_wheel"/>
  <xacro:wheel_link name="rear_left_wheel"/>
  <xacro:wheel_link name="rear_right_wheel"/>

  <!-- Wheel joints -->
  <joint name="front_left_wheel_joint" type="continuous">
    <parent link="base_link"/>
    <child link="front_left_wheel"/>
    <origin xyz="${wheel_x_front} ${wheel_y} ${wheel_z}" rpy="0 0 0"/>
    <axis xyz="0 1 0"/>
  </joint>

  <joint name="front_right_wheel_joint" type="continuous">
    <parent link="base_link"/>
    <child link="front_right_wheel"/>
    <origin xyz="${wheel_x_front} -${wheel_y} ${wheel_z}" rpy="0 0 0"/>
    <axis xyz="0 1 0"/>
  </joint>

  <joint name="rear_left_wheel_joint" type="continuous">
    <parent link="base_link"/>
    <child link="rear_left_wheel"/>
    <origin xyz="${wheel_x_rear} ${wheel_y} ${wheel_z}" rpy="0 0 0"/>
    <axis xyz="0 1 0"/>
  </joint>

  <joint name="rear_right_wheel_joint" type="continuous">
    <parent link="base_link"/>
    <child link="rear_right_wheel"/>
    <origin xyz="${wheel_x_rear} -${wheel_y} ${wheel_z}" rpy="0 0 0"/>
    <axis xyz="0 1 0"/>
  </joint>

    




<!-- Drum (placeholder primitive, prismatic lift + continuous spin) -->
  <xacro:property name="drum_radius" value="0.10"/>
  <xacro:property name="drum_length" value="0.30"/>
  <xacro:property name="drum_mass"   value="1.0"/>

  <!-- Mount at middle of chassis -->
  <xacro:property name="drum_x" value="${base_x/2 + drum_radius + 0.1}"/>
  <xacro:property name="drum_y" value="0.0"/>
  <xacro:property name="drum_z" value="${base_z/2 + drum_radius - 0.1}"/>

  <!-- Drum lift travel: 0 = up (rest), -0.1 = lowered -->
  <xacro:property name="drum_lift_lower" value="-0.1"/>
  <xacro:property name="drum_lift_upper" value="0.0"/>
  <xacro:property name="drum_lift_effort" value="40.0"/>
  <xacro:property name="drum_lift_velocity" value="0.1"/>

  <!-- Drum spin limits -->
  <xacro:property name="drum_spin_effort" value="50.0"/>
  <xacro:property name="drum_spin_velocity" value="10.0"/>

  <!-- Intermediate frame -->
<link name="drum_lift_link">
  <inertial>
    <origin xyz="0 0 0" rpy="0 0 0"/>
    <mass value="2.0"/>
    <inertia ixx="0.01" ixy="0" ixz="0" iyy="0.01" iyz="0" izz="0.01"/>
  </inertial>
</link>

  <!-- Actual drum link: visual, collision, real inertia -->
  <link name="drum_link">
    <visual>
      <origin xyz="0 0 0" rpy="${pi/2} 0 0"/>
      <geometry>
        <cylinder radius="${drum_radius}" length="${drum_length}"/>
      </geometry>
      <material name="blue"/>
    </visual>

    <collision>
      <origin xyz="0 0 0" rpy="${pi/2} 0 0"/>
      <geometry>
        <cylinder radius="${drum_radius}" length="${drum_length}"/>
      </geometry>
    </collision>

    <xacro:inertial_cylinder mass="${drum_mass}" length="${drum_length}" radius="${drum_radius}">
      <origin xyz="0 0 0" rpy="0 0 0"/>
    </xacro:inertial_cylinder>
  </link>

  <!-- Lift joint: prismatic along Z. Origin stays at base_link,
       offset moved down to drum_spin_joint.  change to type prismatic -->
       
  <joint name="drum_joint" type="prismatic">
    <parent link="base_link"/>
    <child link="drum_lift_link"/>
    <origin xyz="0 0 0" rpy="0 0 0"/>
    <axis xyz="0 0 1"/>
    <limit lower="${drum_lift_lower}"
           upper="${drum_lift_upper}"
           effort="${drum_lift_effort}"
           velocity="${drum_lift_velocity}"/>
    <dynamics damping="5.0" friction="50.0"/>
  </joint>

  <!-- Spin joint: continuous around Y. Carries the X/Z offset
       that places the drum at the front of the rover. -->
  <joint name="drum_spin_joint" type="continuous">
    <parent link="drum_lift_link"/>
    <child link="drum_link"/>
    <origin xyz="${drum_x} ${drum_y} ${drum_z}" rpy="0 0 0"/>
    <axis xyz="0 1 0"/>
    <limit effort="${drum_spin_effort}" velocity="${drum_spin_velocity}"/>
    <dynamics damping="0.1" friction="0.05"/>
  </joint>

  <gazebo reference="drum_link">
    <material>Gazebo/Blue</material>
  </gazebo>
  <gazebo>
  <self_collide>0</self_collide>
  </gazebo>
</robot>


